<?xml version="1.0" ?>
<!-- =================================================================================== -->
<!-- |    This document was autogenerated by xacro from robot_base.urdf                | -->
<!-- |    EDITING THIS FILE BY HAND IS NOT RECOMMENDED                                 | -->
<!-- =================================================================================== -->
<robot name="robot_base">
  <link name="base_footprint">
    <inertial>
      <mass value="1.0"/>
      <origin xyz="0 0 0"/>
      <inertia ixx="1.391" ixy="0.004" ixz="0.0" iyy="6.853" iyz="0.0" izz="6.125"/>
    </inertial>
    <visual>
      <origin rpy="1.57079 0 3.1415" xyz="0 0 0"/>
      <geometry>
        <box size="0.001 0.001 0.001"/>
      </geometry>
    </visual>
  </link>
  <joint name="base_footprint_joint" type="fixed">
    <origin rpy="0 0 0" xyz="0 0 0.06"/>
    <parent link="base_footprint"/>
    <child link="base_link"/>
  </joint>
  <!-- BASE_LINK -->
  <link name="base_link">
    <collision>
      <origin rpy="0 0 0" xyz="0 0 0.0"/>
      <geometry>
        <!--<mesh filename="package://mobile_manipulator_body/meshes/robot_base.stl"/>-->
        <box size="0.187 0.203 0.07"/>
      </geometry>
    </collision>
    <inertial>
      <mass value="5.0"/>
      <origin xyz="0 0 0"/>
      <inertia ixx="1.391" ixy="0.004" ixz="0.0" iyy="6.853" iyz="0.0" izz="6.125"/>
    </inertial>
    <visual>
      <origin rpy="0 0 0" xyz="0 0 0"/>
      <geometry>
        <!--<mesh filename="package://mobile_manipulator_body/meshes/robot_base.stl"/>-->
        <box size="0.187 0.203 0.07"/>
      </geometry>
    </visual>
  </link>
  <link name="front_left_wheel">
    <collision>
      <origin rpy="1.5707963267949 0 0" xyz="0 0 0"/>
      <geometry>
        <cylinder length="0.06" radius="0.06"/>
      </geometry>
    </collision>
    <inertial>
      <origin rpy="0 0 0" xyz="-4.1867E-18 0.0068085 -1.65658661799998E-18"/>
      <mass value="0.378"/>
      <inertia ixx="0.00856502765719703" ixy="1.5074118157338E-19" ixz="-4.78150098725052E-19" iyy="0.013670640432096" iyz="-2.68136447099727E-19" izz="0.00856502765719703"/>
    </inertial>
    <visual>
      <origin rpy="1.5707963267949 0 0" xyz="0 0 0"/>
      <geometry>
        <cylinder length="0.06" radius="0.06"/>
      </geometry>
      <material name="">
        <color rgba="0.79216 0.81961 0.93333 1"/>
      </material>
    </visual>
  </link>
  <link name="front_right_wheel">
    <collision>
      <origin rpy="1.5707963267949 0 0" xyz="0 0 0"/>
      <geometry>
        <cylinder length="0.06" radius="0.06"/>
      </geometry>
    </collision>
    <inertial>
      <origin rpy="0 0 0" xyz="-4.1867E-18 0.0068085 -1.65658661799998E-18"/>
      <mass value="0.378"/>
      <inertia ixx="0.00856502765719703" ixy="1.5074118157338E-19" ixz="-4.78150098725052E-19" iyy="0.013670640432096" iyz="-2.68136447099727E-19" izz="0.00856502765719703"/>
    </inertial>
    <visual>
      <origin rpy="1.5707963267949 0 0" xyz="0 0 0"/>
      <geometry>
        <cylinder length="0.06" radius="0.06"/>
      </geometry>
      <material name="">
        <color rgba="0.79216 0.81961 0.93333 1"/>
      </material>
    </visual>
  </link>
  <link name="rear_left_wheel">
    <collision>
      <origin rpy="1.5707963267949 0 0" xyz="0 0 0"/>
      <geometry>
        <cylinder length="0.06" radius="0.06"/>
      </geometry>
    </collision>
    <inertial>
      <origin rpy="0 0 0" xyz="-4.1867E-18 0.0068085 -1.65658661799998E-18"/>
      <mass value="0.378"/>
      <inertia ixx="0.00856502765719703" ixy="1.5074118157338E-19" ixz="-4.78150098725052E-19" iyy="0.013670640432096" iyz="-2.68136447099727E-19" izz="0.00856502765719703"/>
    </inertial>
    <visual>
      <origin rpy="1.5707963267949 0 0" xyz="0 0 0"/>
      <geometry>
        <cylinder length="0.06" radius="0.06"/>
      </geometry>
      <material name="">
        <color rgba="0.79216 0.81961 0.93333 1"/>
      </material>
    </visual>
  </link>
  <link name="rear_right_wheel">
    <collision>
      <origin rpy="1.5707963267949 0 0" xyz="0 0 0"/>
      <geometry>
        <cylinder length="0.06" radius="0.06"/>
      </geometry>
    </collision>
    <inertial>
      <origin rpy="0 0 0" xyz="-4.1867E-18 0.0068085 -1.65658661799998E-18"/>
      <mass value="0.378"/>
      <inertia ixx="0.00856502765719703" ixy="1.5074118157338E-19" ixz="-4.78150098725052E-19" iyy="0.013670640432096" iyz="-2.68136447099727E-19" izz="0.00856502765719703"/>
    </inertial>
    <visual>
      <origin rpy="1.5707963267949 0 0" xyz="0 0 0"/>
      <geometry>
        <cylinder length="0.06" radius="0.06"/>
      </geometry>
      <material name="">
        <color rgba="0.79216 0.81961 0.93333 1"/>
      </material>
    </visual>
  </link>
  <joint name="front_left_wheel_joint" type="continuous">
    <axis xyz="0 1 0"/>
    <parent link="base_link"/>
    <child link="front_left_wheel"/>
    <origin rpy="0 0 0" xyz="0.09 0.14 0"/>
  </joint>
  <joint name="front_right_wheel_joint" type="continuous">
    <axis xyz="0 1 0"/>
    <parent link="base_link"/>
    <child link="front_right_wheel"/>
    <origin rpy="0 0 0" xyz="0.09 -0.14 0"/>
  </joint>
  <joint name="rear_left_wheel_joint" type="continuous">
    <axis xyz="0 1 0"/>
    <parent link="base_link"/>
    <child link="rear_left_wheel"/>
    <origin rpy="0 0 0" xyz="-0.09 0.14 0"/>
  </joint>
  <joint name="rear_right_wheel_joint" type="continuous">
    <axis xyz="0 1 0"/>
    <parent link="base_link"/>
    <child link="rear_right_wheel"/>
    <origin rpy="0 0 0" xyz="-0.09 -0.14 0"/>
  </joint>
  <transmission name="front_left_wheel_trans" type="SimpleTransmission">
    <type>transmission_interface/SimpleTransmission</type>
    <!---  <actuator name="${prefix}_wheel_motor"> 

  	<hardwareInterface>hardware_interface/VelocityJointInterface</hardwareInterface> 

  	<mechanicalReduction>1</mechanicalReduction> 

  </actuator> -->
    <joint name="front_left_wheel_joint">
      <hardwareInterface>hardware_interface/VelocityJointInterface</hardwareInterface>
    </joint>
  </transmission>
  <transmission name="front_right_wheel_trans" type="SimpleTransmission">
    <type>transmission_interface/SimpleTransmission</type>
    <!---  <actuator name="${prefix}_wheel_motor"> 

  	<hardwareInterface>hardware_interface/VelocityJointInterface</hardwareInterface> 

  	<mechanicalReduction>1</mechanicalReduction> 

  </actuator> -->
    <joint name="front_right_wheel_joint">
      <hardwareInterface>hardware_interface/VelocityJointInterface</hardwareInterface>
    </joint>
  </transmission>
  <transmission name="rear_left_wheel_trans" type="SimpleTransmission">
    <type>transmission_interface/SimpleTransmission</type>
    <!---  <actuator name="${prefix}_wheel_motor"> 

  	<hardwareInterface>hardware_interface/VelocityJointInterface</hardwareInterface> 

  	<mechanicalReduction>1</mechanicalReduction> 

  </actuator> -->
    <joint name="rear_left_wheel_joint">
      <hardwareInterface>hardware_interface/VelocityJointInterface</hardwareInterface>
    </joint>
  </transmission>
  <transmission name="rear_right_wheel_trans" type="SimpleTransmission">
    <type>transmission_interface/SimpleTransmission</type>
    <!---  <actuator name="${prefix}_wheel_motor"> 

  	<hardwareInterface>hardware_interface/VelocityJointInterface</hardwareInterface> 

  	<mechanicalReduction>1</mechanicalReduction> 

  </actuator> -->
    <joint name="rear_right_wheel_joint">
      <hardwareInterface>hardware_interface/VelocityJointInterface</hardwareInterface>
    </joint>
  </transmission>
  <gazebo reference="front_left_wheel">
    <ode>
      <mu1 value="0.80"/>
      <mu2 value="0.2"/>
      <kp value="1000.0"/>
      <kd value="1.0"/>
      <fdir1 value="1 0 0"/>
      <slip1>0</slip1>
      <slip2>0</slip2>
    </ode>
  </gazebo>
  <gazebo reference="front_right_wheel">
    <ode>
      <mu1 value="0.80"/>
      <mu2 value="0.2"/>
      <kp value="1000.0"/>
      <kd value="1.0"/>
      <fdir1 value="1 0 0"/>
      <slip1>0</slip1>
      <slip2>0</slip2>
    </ode>
  </gazebo>
  <gazebo reference="rear_left_wheel">
    <ode>
      <mu1 value="0.80"/>
      <mu2 value="0.2"/>
      <kp value="1000.0"/>
      <kd value="1.0"/>
      <fdir1 value="1 0 0"/>
      <slip1>0</slip1>
      <slip2>0</slip2>
    </ode>
  </gazebo>
  <gazebo reference="rear_right_wheel">
    <ode>
      <mu1 value="0.80"/>
      <mu2 value="0.2"/>
      <kp value="1000.0"/>
      <kd value="1.0"/>
      <fdir1 value="1 0 0"/>
      <slip1>0</slip1>
      <slip2>0</slip2>
    </ode>
  </gazebo>
  <!-- <xacro:driver/>

<xacro:robot_camera/> 

<xacro:robot_lidar/> -->
</robot>
